<?xml version="1.0"?>
<robot xmlns:xacro="http://ros.org/wiki/xacro">
  <xacro:include filename="$(find robotiq_2f_85_gripper_digit_visualization)/urdf/robotiq_arg2f_transmission.xacro" />

  <xacro:macro name="outer_knuckle" params="prefix fingerprefix stroke">
    <link name="${prefix}${fingerprefix}_outer_knuckle">
      <inertial>
        <origin xyz="-0.000200000000003065 0.0199435877845359 0.0292245259211331" rpy="0 0 0" />
        <mass value="0.00853198276973456" />
        <inertia ixx="2.89328108496468E-06" ixy="-1.57935047237397E-19" ixz="-1.93980378593255E-19" iyy="1.86719750325683E-06" iyz="-1.21858577871576E-06" izz="1.21905238907251E-06" />
        </inertial>
      <visual>
        <origin xyz="0 0 0" rpy="0 0 0" />
        <geometry>
          <mesh filename="package://robotiq_2f_85_gripper_digit_visualization/meshes/visual/robotiq_arg2f_85_outer_knuckle.dae" scale="0.001 0.001 0.001"/>
        </geometry>
        <material name="">
          <color rgba="0.792156862745098 0.819607843137255 0.933333333333333 1" />
        </material>
      </visual>
      <collision>
        <origin xyz="0 0 0" rpy="0 0 0" />
        <geometry>
          <mesh filename="package://robotiq_2f_85_gripper_digit_visualization/meshes/collision/robotiq_arg2f_85_outer_knuckle.dae" scale="0.001 0.001 0.001"/>
        </geometry>
      </collision>
    </link>
  </xacro:macro>

  <xacro:macro name="outer_finger" params="prefix fingerprefix stroke">
    <link name="${prefix}${fingerprefix}_outer_finger">
      <inertial>
        <origin xyz="0.00030115855001899 0.0373907951953854 -0.0208027427000385" rpy="0 0 0" />
        <mass value="0.022614240507152" />
        <inertia ixx="1.52518312458174E-05" ixy="9.76583423954399E-10" ixz="-5.43838577022588E-10" iyy="6.17694243867776E-06" iyz="6.78636130740228E-06" izz="1.16494917907219E-05" />
        </inertial>
      <visual>
        <origin xyz="0 0 0" rpy="0 0 0" />
        <geometry>
          <mesh filename="package://robotiq_2f_85_gripper_digit_visualization/meshes/visual/robotiq_arg2f_85_outer_finger.dae" scale="0.001 0.001 0.001"/>
        </geometry>
        <material name="">
          <color rgba="0.1 0.1 0.1 1" />
        </material>
      </visual>
      <collision>
        <origin xyz="0 0 0" rpy="0 0 0" />
        <geometry>
          <mesh filename="package://robotiq_2f_85_gripper_digit_visualization/meshes/collision/robotiq_arg2f_85_outer_finger.dae" scale="0.001 0.001 0.001"/>
        </geometry>
      </collision>
    </link>
  </xacro:macro>

  <xacro:macro name="inner_knuckle" params="prefix fingerprefix stroke">
    <link name="${prefix}${fingerprefix}_inner_knuckle">
      <inertial>
        <origin xyz="0.000123011831763771 0.0507850843201817 0.00103968640075166" rpy="0 0 0" />
        <mass value="0.0271177346495152" />
        <inertia ixx="2.61910379223783E-05" ixy="-2.43616858946494E-07" ixz="-6.37789906117123E-09" iyy="2.8270243746167E-06" iyz="-5.37200748039765E-07" izz="2.83695868220296E-05" />
        </inertial>
      <visual>
        <origin xyz="0 0 0" rpy="0 0 0" />
        <geometry>
          <mesh filename="package://robotiq_2f_85_gripper_digit_visualization/meshes/visual/robotiq_arg2f_85_inner_knuckle.dae" scale="0.001 0.001 0.001"/>
        </geometry>
        <material name="">
          <color rgba="0.1 0.1 0.1 1" />
        </material>
      </visual>
      <collision>
        <origin xyz="0 0 0" rpy="0 0 0" />
        <geometry>
          <mesh filename="package://robotiq_2f_85_gripper_digit_visualization/meshes/collision/robotiq_arg2f_85_inner_knuckle.dae" scale="0.001 0.001 0.001"/>
        </geometry>
      </collision>
    </link>
  </xacro:macro>

  <xacro:macro name="inner_finger" params="prefix fingerprefix stroke">
    <link name="${prefix}${fingerprefix}_inner_finger">
      <inertial>
        <origin xyz="0.000299999999999317 0.0160078233491243 -0.0136945669206257" rpy="0 0 0" />
        <mass value="0.0104003125914103" />
        <inertia ixx="2.71909453810972E-06" ixy="1.35402465472579E-21" ixz="-7.1817349065269E-22" iyy="7.69100314106116E-07" iyz="6.74715432769696E-07" izz="2.30315190420171E-06" />
        </inertial>
      <visual>
        <origin xyz="0 0 0" rpy="0 0 0" />
        <geometry>
          <mesh filename="package://robotiq_2f_85_gripper_digit_visualization/meshes/visual/robotiq_arg2f_85_inner_finger.dae" scale="0.001 0.001 0.001"/>
        </geometry>
        <material name="">
          <color rgba="0.1 0.1 0.1 1" />
        </material>
      </visual>
      <collision>
        <origin xyz="0 0 0" rpy="0 0 0" />
        <geometry>
          <mesh filename="package://robotiq_2f_85_gripper_digit_visualization/meshes/collision/robotiq_arg2f_85_inner_finger.dae" scale="0.001 0.001 0.001" />
        </geometry>
      </collision>
    </link>
  </xacro:macro>


  <xacro:macro name="inner_finger_digit_adapter" params="prefix fingerprefix stroke">
    <link name="${prefix}${fingerprefix}_inner_finger">
      <inertial>
        <origin xyz="0.000299999999999317 0.0160078233491243 -0.0136945669206257" rpy="0 0 0" />
        <mass value="0.0104003125914103" />
        <inertia ixx="2.71909453810972E-06" ixy="1.35402465472579E-21" ixz="-7.1817349065269E-22" iyy="7.69100314106116E-07" iyz="6.74715432769696E-07" izz="2.30315190420171E-06" />
        </inertial>
      <visual>
        <origin xyz="0 0 0" rpy="0 0 0" />
        <geometry>
          <mesh filename="package://digit_gazebo_launch/meshes/digit/digit_adapter_edited.dae" scale="0.001 0.001 0.001"/>
        </geometry>
        <material name="">
          <color rgba="0.1 0.1 0.1 1" />
        </material>
      </visual>
      <collision>
        <origin xyz="0 0 0" rpy="0 0 0" />
        <geometry>
          <mesh filename="package://digit_gazebo_launch/meshes/digit/digit_adapter_edited.dae" scale="0.001 0.001 0.001"/>
        </geometry>
      </collision>
    </link>
  </xacro:macro>


  <!-- Finger pad link, the default are the "big pads" with rubber-->
  <xacro:macro name="inner_finger_pad" params="prefix fingerprefix">
    <link name="${prefix}${fingerprefix}_inner_finger_pad">
      <visual>
        <origin xyz="0 0 0" rpy="0 0 0" />
        <geometry>
          <box size="0.022 0.00635 0.0375"/>
        </geometry>
        <material name="">
          <color rgba="0.9 0.9 0.9 1" />
        </material>
      </visual>
      <collision>
        <origin xyz="0 0 0" rpy="0 0 0" />
        <geometry>
          <box size="0.022 0.00635 0.0375"/>
        </geometry>
        <material name="">
          <color rgba="0.9 0.0 0.0 1" />
        </material>
      </collision>
    </link>
  </xacro:macro>

  <!--A full DIGIT has dimensions 20 mm width x 27 mm height x 18 mm depth, and weighs approximately 20 g: based on this i calculated the inertia matrix
  https://www.seas.upenn.edu/~dineshj/publication/lambeta-2020-digit/lambeta-2020-digit.pdf-->
  <xacro:macro name="digit" params="prefix fingerprefix">
  <link concave="yes" name="${prefix}${fingerprefix}_digit">
    <inertial>
      <origin rpy="0 0 0" xyz="0 0 0"/>
       <mass value=".02"/>
       <inertia ixx="2.9875E-8" ixy="0" ixz="0" iyy="1.273E-8" iyz="0" izz="3.2025E-8"/>
    </inertial> 
    <visual> 
    <origin xyz="0 0  0" rpy="0 -1.57079632679 1.57079632679"/>
      <geometry>
				<mesh filename="package://digit_gazebo_launch/meshes/digit/digit.STL" scale="1 1 1"/>
      </geometry>
      <material name="white">
        <color rgba="1 1 1 1"/>
      </material>
    </visual>
    <collision concave="yes">
    <origin xyz="0 0  0" rpy="0 -1.57079632679 1.57079632679"/>
      <geometry>
				<mesh filename="package://digit_gazebo_launch/meshes/digit/digit.STL" scale="1 1 1"/>
      </geometry>
    </collision>
  </link>
  </xacro:macro>


  <xacro:macro name="outer_finger_joint" params="prefix fingerprefix">
    <joint name="${prefix}${fingerprefix}_outer_finger_joint" type="fixed">
      <origin xyz="0 0.0315 -0.0041" rpy="0 0 0"/>
      <parent link="${prefix}${fingerprefix}_outer_knuckle" />
      <child link="${prefix}${fingerprefix}_outer_finger" />
      <axis xyz="1 0 0" />
    </joint>
  </xacro:macro>

  <xacro:macro name="inner_knuckle_joint" params="prefix fingerprefix reflect">
    <joint name="${prefix}${fingerprefix}_inner_knuckle_joint" type="revolute">
      <!-- <origin xyz="0 ${reflect * -0.0127} 0.06142" rpy="${pi / 2 + .725} 0 ${(reflect - 1) * pi / 2}" /> -->
      <origin xyz="0 ${reflect * -0.0127} 0.06142" rpy="0 0 ${(1 + reflect) * pi / 2}"/>
      <parent link="${prefix}robotiq_arg2f_base_link" />
      <child link="${prefix}${fingerprefix}_inner_knuckle" />
      <axis xyz="1 0 0" />
      <limit lower="0" upper="0.8757" velocity="2.0" effort="1000" />
      <!-- <mimic joint="${prefix}finger_joint" multiplier="1" offset="0" /> -->
    </joint>

    <transmission name="${prefix}${fingerprefix}_inner_knuckle_joint_trans">
      <type>transmission_interface/SimpleTransmission</type>
      <joint name="${prefix}${fingerprefix}_inner_knuckle_joint">
        <hardwareInterface>hardware_interface/PositionJointInterface</hardwareInterface>
      </joint>
      <actuator name="${prefix}${fingerprefix}_inner_knuckle_joint_motor">
        <mechanicalReduction>1</mechanicalReduction>
      </actuator>
    </transmission>
  </xacro:macro>

  <xacro:macro name="inner_finger_joint" params="prefix fingerprefix">
    <joint name="${prefix}${fingerprefix}_inner_finger_joint" type="revolute">
      <origin xyz="0 0.0061 0.0471" rpy="0 0 0"/>
      <parent link="${prefix}${fingerprefix}_outer_finger" />
      <child link="${prefix}${fingerprefix}_inner_finger" />
      <axis xyz="1 0 0" />
      <!-- <limit lower="0" upper="0.8757" velocity="2.0" effort="1000" /> -->
      <limit lower="-0.8757" upper="0" velocity="2.0" effort="1000" />
      <!--<mimic joint="${prefix}finger_joint" multiplier="-1" offset="0" /> -->
    </joint>


    <transmission name="${prefix}${fingerprefix}_inner_finger_joint_trans">
      <type>transmission_interface/SimpleTransmission</type>
      <joint name="${prefix}${fingerprefix}_inner_finger_joint">
        <hardwareInterface>hardware_interface/PositionJointInterface</hardwareInterface>
      </joint>
      <actuator name="${prefix}${fingerprefix}_inner_finger_joint_motor">
        <mechanicalReduction>1</mechanicalReduction>
      </actuator>
    </transmission>
  </xacro:macro>

  <xacro:macro name="inner_finger_pad_joint" params="prefix fingerprefix">
    <joint name="${prefix}${fingerprefix}_inner_finger_pad_joint" type="fixed">
      <origin xyz="0 -0.0220203446692936 0.03242" rpy="0 0 0"/>
      <parent link="${prefix}${fingerprefix}_inner_finger" />
      <child link="${prefix}${fingerprefix}_inner_finger_pad" />
      <axis xyz="0 0 1" />
    </joint>
  </xacro:macro>

  <!-- I set the joint to revolute so i can get it's contacts as a topic -->
  <xacro:macro name="digit_joint" params="prefix fingerprefix">
    <joint name="${prefix}${fingerprefix}_digit_joint" type="fixed">
      <origin xyz="0 0.002 0.0465" rpy="0 0 0"/>
      <parent link="${prefix}${fingerprefix}_inner_finger" />
      <child link="${prefix}${fingerprefix}_digit" />
    </joint>

    <link name="digit_link">
    </link>
        <joint name="digit_link_joint" type="fixed">
      <origin xyz="0 0 0" rpy="0 -1.57079632679 1.57079632679"/>
      <parent link="${prefix}${fingerprefix}_digit" />
      <child link="digit_link" />
    </joint>

  </xacro:macro>

  <xacro:include filename="$(find robotiq_2f_85_gripper_digit_visualization)/urdf/robotiq_arg2f_digit.xacro" />

  <xacro:macro name="finger_joint" params="prefix">
    <joint name="${prefix}finger_joint" type="revolute">
      <origin xyz="0 -0.0306011 0.054904" rpy="0 0 ${pi}"/>
      <parent link="${prefix}robotiq_arg2f_base_link" />
      <child link="${prefix}left_outer_knuckle" />
      <axis xyz="1 0 0" />
      <limit lower="0" upper="0.8" velocity="2.0" effort="1000" />
    </joint>
    <xacro:finger_joints prefix="${prefix}" fingerprefix="left" reflect="1.0"/>
  </xacro:macro>

  <xacro:macro name="right_outer_knuckle_joint" params="prefix">
    <joint name="${prefix}right_outer_knuckle_joint" type="revolute">
      <origin xyz="0 0.0306011 0.054904" rpy="0 0 0"/>
      <parent link="${prefix}robotiq_arg2f_base_link" />
      <child link="${prefix}right_outer_knuckle" />
      <axis xyz="1 0 0" />
      <limit lower="0" upper="0.81" velocity="2.0" effort="1000" />
      <!--<mimic joint="${prefix}finger_joint" multiplier="1" offset="0" /> -->
    </joint>

    <transmission name="${prefix}right_outer_knuckle_joint_trans">
      <type>transmission_interface/SimpleTransmission</type>
      <joint name="${prefix}right_outer_knuckle_joint">
        <hardwareInterface>hardware_interface/PositionJointInterface</hardwareInterface>
      </joint>
      <actuator name="${prefix}right_outer_knuckle_joint_motor">
        <mechanicalReduction>1</mechanicalReduction>
      </actuator>
    </transmission>
    <xacro:finger_joints prefix="${prefix}" fingerprefix="right" reflect="-1.0"/>
  </xacro:macro>

  <!-- Initialization of all joints and links -->
  <xacro:macro name="robotiq_arg2f_85" params="prefix">
    <xacro:robotiq_arg2f_base_link prefix="${prefix}"/>
    <xacro:finger_links prefix="${prefix}" fingerprefix="left" stroke="85"/>
    <xacro:finger_links prefix="${prefix}" fingerprefix="right" stroke="85"/>
    <xacro:finger_joint prefix="${prefix}"/>
    <xacro:right_outer_knuckle_joint prefix="${prefix}"/>
    <!-- Digit only on the left finger -->
    <xacro:digit prefix="${prefix}" fingerprefix="left"/>
    <xacro:digit_joint prefix="${prefix}" fingerprefix="left"/> 
    <xacro:robotiq_arg2f_transmission prefix="${prefix}"/>
  </xacro:macro>
</robot>
